2025-10-07 14:37:36.125 Uncaught app exception
Traceback (most recent call last):
  File "/Users/aakashbhatt/referral-outreach-app/venv/lib/python3.10/site-packages/sqlalchemy/engine/base.py", line 1969, in _exec_single_context
    self.dialect.do_execute(
  File "/Users/aakashbhatt/referral-outreach-app/venv/lib/python3.10/site-packages/sqlalchemy/engine/default.py", line 922, in do_execute
    cursor.execute(statement, parameters)
sqlite3.OperationalError: no such column: email_campaigns.user_id

The above exception was the direct cause of the following exception:

Traceback (most recent call last):
  File "/Users/aakashbhatt/referral-outreach-app/venv/lib/python3.10/site-packages/streamlit/runtime/scriptrunner/script_runner.py", line 535, in _run_script
    exec(code, module.__dict__)
  File "/Users/aakashbhatt/referral-outreach-app/app.py", line 427, in <module>
    campaigns = session.query(EmailCampaign).order_by(EmailCampaign.created_at.desc()).all()
  File "/Users/aakashbhatt/referral-outreach-app/venv/lib/python3.10/site-packages/sqlalchemy/orm/query.py", line 2693, in all
    return self._iter().all()  # type: ignore
  File "/Users/aakashbhatt/referral-outreach-app/venv/lib/python3.10/site-packages/sqlalchemy/orm/query.py", line 2847, in _iter
    result: Union[ScalarResult[_T], Result[_T]] = self.session.execute(
  File "/Users/aakashbhatt/referral-outreach-app/venv/lib/python3.10/site-packages/sqlalchemy/orm/session.py", line 2308, in execute
    return self._execute_internal(
  File "/Users/aakashbhatt/referral-outreach-app/venv/lib/python3.10/site-packages/sqlalchemy/orm/session.py", line 2190, in _execute_internal
    result: Result[Any] = compile_state_cls.orm_execute_statement(
  File "/Users/aakashbhatt/referral-outreach-app/venv/lib/python3.10/site-packages/sqlalchemy/orm/context.py", line 293, in orm_execute_statement
    result = conn.execute(
  File "/Users/aakashbhatt/referral-outreach-app/venv/lib/python3.10/site-packages/sqlalchemy/engine/base.py", line 1416, in execute
    return meth(
  File "/Users/aakashbhatt/referral-outreach-app/venv/lib/python3.10/site-packages/sqlalchemy/sql/elements.py", line 517, in _execute_on_connection
    return connection._execute_clauseelement(
  File "/Users/aakashbhatt/referral-outreach-app/venv/lib/python3.10/site-packages/sqlalchemy/engine/base.py", line 1639, in _execute_clauseelement
    ret = self._execute_context(
  File "/Users/aakashbhatt/referral-outreach-app/venv/lib/python3.10/site-packages/sqlalchemy/engine/base.py", line 1848, in _execute_context
    return self._exec_single_context(
  File "/Users/aakashbhatt/referral-outreach-app/venv/lib/python3.10/site-packages/sqlalchemy/engine/base.py", line 1988, in _exec_single_context
    self._handle_dbapi_exception(
  File "/Users/aakashbhatt/referral-outreach-app/venv/lib/python3.10/site-packages/sqlalchemy/engine/base.py", line 2344, in _handle_dbapi_exception
    raise sqlalchemy_exception.with_traceback(exc_info[2]) from e
  File "/Users/aakashbhatt/referral-outreach-app/venv/lib/python3.10/site-packages/sqlalchemy/engine/base.py", line 1969, in _exec_single_context
    self.dialect.do_execute(
  File "/Users/aakashbhatt/referral-outreach-app/venv/lib/python3.10/site-packages/sqlalchemy/engine/default.py", line 922, in do_execute
    cursor.execute(statement, parameters)
sqlalchemy.exc.OperationalError: (sqlite3.OperationalError) no such column: email_campaigns.user_id
[SQL: SELECT email_campaigns.id AS email_campaigns_id, email_campaigns.user_id AS email_campaigns_user_id, email_campaigns.job_title AS email_campaigns_job_title, email_campaigns.company AS email_campaigns_company, email_campaigns.job_description AS email_campaigns_job_description, email_campaigns.created_at AS email_campaigns_created_at 
FROM email_campaigns ORDER BY email_campaigns.created_at DESC]
(Background on this error at: https://sqlalche.me/e/20/e3q8)
